[2024-05-10T23:30:59.263+0000] {task_context_logger.py:104} ERROR - Executor reports task instance <TaskInstance: process_sales.extract_data_from_api scheduled__2022-08-12T01:00:00+00:00 [queued]> finished (success) although the task says it's queued. (Info: None) Was the task killed externally?
