[2024-05-10T23:29:11.096+0000] {task_context_logger.py:104} ERROR - Executor reports task instance <TaskInstance: process_sales.extract_data_from_api manual__2024-05-06T22:01:10.120021+00:00 [queued]> finished (success) although the task says it's queued. (Info: None) Was the task killed externally?
